Workbook

Sheet READ ME FIRST
A1: CSE A1 Master Attendance Workbook (Multi-Column Structure)
A3: WHAT'S FIXED:
A4: • Detailed Attendance now has MULTIPLE SUBJECT COLUMNS under each Date (based on the exact timetable).
A5: • Monthly, Subject-wise, and Overall summaries are 100% formula-driven and linked to the new layout.
A6: • Just type 'P' or 'A' in the yellow cells. All percentages and totals will update instantly.
A8: NOTE: Subject-wise summary tracks core theory subjects (PSQT, OOPJ, OS, COA, DMS). Labs/Activities are tracked in Detailed Attendance.

Sheet Monthly Guide
A1: HOW TO ADD SEPTEMBER, OCTOBER, NOVEMBER…
A3: 1. Keep the existing June–August workbook sheets unchanged.
A4: 2. Duplicate the 'MONTHLY TEMPLATE' sheet and rename it to the required month, e.g. 'October 2026'.
A5: 3. Use the official timetable to create the date/class columns. The September sheet is already populated as the worked example.
A6: 4. For each class, set the bulk status to ☑ Present, then change only the absent students to ☐.
A7: 5. Theory classes apply to all 124 students. Lab slots respect the existing Batch 1/2/3 allocation.
A8: 6. Do not put NCC/NSS, Remedial, Library/Self Study, or Swachh Bharat into subject attendance calculations.
A9: 7. The existing June–August output sheets are intentionally preserved. A future final version can connect the new monthly sheets to a dynamic semester summary.

Sheet Detailed Attendance
A1: S.No | B1: Registration No | C1: Student Name | D1: 29-Jun | H1: 30-Jun | L1: 01-Jul | P1: 02-Jul | T1: 03-Jul | X1: 06-Jul | AB1: 07-Jul | AF1: 08-Jul | AJ1: 09-Jul | AN1: 10-Jul | AR1: 13-Jul | AV1: 14-Jul | AZ1: 15-Jul | BD1: 16-Jul | BH1: 17-Jul | BL1: 20-Jul | BP1: 21-Jul | BT1: 22-Jul | BX1: 23-Jul | CB1: 24-Jul | CF1: 25-Jul | CI1: 27-Jul | CM1: 28-Jul | CQ1: 29-Jul | CU1: 30-Jul | CY1: 31-Jul | DC1: 01-Aug | DF1: 03-Aug | DJ1: 04-Aug | DN1: 05-Aug | DR1: 06-Aug | DV1: 07-Aug | DZ1: 08-Aug | EC1: 10-Aug | EG1: 11-Aug | EK1: 12-Aug | EO1: 13-Aug | ES1: 14-Aug | EW1: 17-Aug | FA1: 18-Aug | FE1: 19-Aug | FI1: 20-Aug | FM1: 24-Aug | FQ1: 25-Aug | FU1: 26-Aug | FY1: 27-Aug | GC1: 28-Aug | GG1: 29-Aug
D2: COA | E2: COA LAB-1 / OS LAB-3 | F2: REMEDIAL CLASS | G2: NCC/NSS | H2: OOPJ LAB-3 | I2: OOPJ | J2: LIBRARY / SELF STUDY | K2: NCC/NSS | L2: OS | M2: DMS | N2: SWATCH BHARAT | O2: NCC/NSS | P2: OS | Q2: OOPJ | R2: PSQT | S2: NCC/NSS | T2: COA | U2: DMS | V2: OS LAB-1 / OOPJ LAB-2 | W2: NCC/NSS | X2: PSQT | Y2: COA LAB-1 / OS LAB-3 | Z2: REMEDIAL CLASS | AA2: NCC/NSS | AB2: OOPJ LAB-3 | AC2: OOPJ | AD2: LIBRARY / SELF STUDY | AE2: NCC/NSS | AF2: OS | AG2: DMS | AH2: SWATCH BHARAT | AI2: NCC/NSS | AJ2: OS | AK2: OOPJ | AL2: PSQT | AM2: NCC/NSS | AN2: COA | AO2: DMS | AP2: OS LAB-1 / OOPJ LAB-2 | AQ2: NCC/NSS | AR2: COA | AS2: COA LAB-1 / OS LAB-3 | AT2: REMEDIAL CLASS | AU2: NCC/NSS | AV2: OOPJ LAB-3 | AW2: OOPJ | AX2: LIBRARY / SELF STUDY | AY2: NCC/NSS | AZ2: OS | BA2: DMS | BB2: SWATCH BHARAT | BC2: NCC/NSS | BD2: OS | BE2: OOPJ | BF2: PSQT | BG2: NCC/NSS | BH2: COA | BI2: DMS | BJ2: OS LAB-1 / OOPJ LAB-2 | BK2: NCC/NSS | BL2: PSQT | BM2: COA LAB-1 / OS LAB-3 | BN2: REMEDIAL CLASS | BO2: NCC/NSS | BP2: OOPJ LAB-3 | BQ2: OOPJ | BR2: LIBRARY / SELF STUDY | BS2: NCC/NSS | BT2: OS | BU2: DMS | BV2: SWATCH BHARAT | BW2: NCC/NSS | BX2: OS | BY2: OOPJ | BZ2: PSQT | CA2: NCC/NSS | CB2: COA | CC2: DMS | CD2: OS LAB-1 / OOPJ LAB-2 | CE2: NCC/NSS | CF2: COA | CG2: COA LAB-2 | CH2: OS LAB-2 / OOPJ LAB-1 / COA LAB-3 | CI2: PSQT | CJ2: COA LAB-1 / OS LAB-3 | CK2: REMEDIAL CLASS | CL2: NCC/NSS | CM2: OOPJ LAB-3 | CN2: OOPJ | CO2: LIBRARY / SELF STUDY | CP2: NCC/NSS | CQ2: OS | CR2: DMS | CS2: SWATCH BHARAT | CT2: NCC/NSS | CU2: OS | CV2: OOPJ | CW2: PSQT | CX2: NCC/NSS | CY2: COA | CZ2: DMS | DA2: OS LAB-1 / OOPJ LAB-2 | DB2: NCC/NSS | DC2: COA | DD2: COA LAB-2 | DE2: OS LAB-2 / OOPJ LAB-1 / COA LAB-3 | DF2: PSQT | DG2: COA LAB-1 / OS LAB-3 | DH2: REMEDIAL CLASS | DI2: NCC/NSS | DJ2: OOPJ LAB-3 | DK2: OOPJ | DL2: LIBRARY / SELF STUDY | DM2: NCC/NSS | DN2: OS | DO2: DMS | DP2: SWATCH BHARAT | DQ2: NCC/NSS | DR2: OS | DS2: OOPJ | DT2: PSQT | DU2: NCC/NSS | DV2: COA | DW2: DMS | DX2: OS LAB-1 / OOPJ LAB-2 | DY2: NCC/NSS | DZ2: COA | EA2: COA LAB-2 | EB2: OS LAB-2 / OOPJ LAB-1 / COA LAB-3 | EC2: PSQT | ED2: COA LAB-1 / OS LAB-3 | EE2: REMEDIAL CLASS | EF2: NCC/NSS | EG2: OOPJ LAB-3 | EH2: OOPJ | EI2: LIBRARY / SELF STUDY | EJ2: NCC/NSS | EK2: OS | EL2: DMS | EM2: SWATCH BHARAT | EN2: NCC/NSS | EO2: OS | EP2: OOPJ | EQ2: PSQT | ER2: NCC/NSS | ES2: COA | ET2: DMS | EU2: OS LAB-1 / OOPJ LAB-2 | EV2: NCC/NSS | EW2: PSQT | EX2: COA LAB-1 / OS LAB-3 | EY2: REMEDIAL CLASS | EZ2: NCC/NSS | FA2: OOPJ LAB-3 | FB2: OOPJ | FC2: LIBRARY / SELF STUDY | FD2: NCC/NSS | FE2: OS | FF2: DMS | FG2: SWATCH BHARAT | FH2: NCC/NSS | FI2: OS | FJ2: OOPJ | FK2: PSQT | FL2: NCC/NSS | FM2: PSQT | FN2: COA LAB-1 / OS LAB-3 | FO2: REMEDIAL CLASS | FP2: NCC/NSS | FQ2: OOPJ LAB-3 | FR2: OOPJ | FS2: LIBRARY / SELF STUDY | FT2: NCC/NSS | FU2: OS | FV2: DMS | FW2: SWATCH BHARAT | FX2: NCC/NSS | FY2: OS | FZ2: OOPJ | GA2: PSQT | GB2: NCC/NSS | GC2: COA | GD2: DMS | GE2: OS LAB-1 / OOPJ LAB-2 | GF2: NCC/NSS | GG2: COA | GH2: COA LAB-2 | GI2: OS LAB-2 / OOPJ LAB-1 / COA LAB-3
D3: Mon | E3: Mon | F3: Mon | G3: Mon | H3: Tue | I3: Tue | J3: Tue | K3: Tue | L3: Wed | M3: Wed | N3: Wed | O3: Wed | P3: Thu | Q3: Thu | R3: Thu | S3: Thu | T3: Fri | U3: Fri | V3: Fri | W3: Fri | X3: Mon | Y3: Mon | Z3: Mon | AA3: Mon | AB3: Tue | AC3: Tue | AD3: Tue | AE3: Tue | AF3: Wed | AG3: Wed | AH3: Wed | AI3: Wed | AJ3: Thu | AK3: Thu | AL3: Thu | AM3: Thu | AN3: Fri | AO3: Fri | AP3: Fri | AQ3: Fri | AR3: Mon | AS3: Mon | AT3: Mon | AU3: Mon | AV3: Tue | AW3: Tue | AX3: Tue | AY3: Tue | AZ3: Wed | BA3: Wed | BB3: Wed | BC3: Wed | BD3: Thu | BE3: Thu | BF3: Thu | BG3: Thu | BH3: Fri | BI3: Fri | BJ3: Fri | BK3: Fri | BL3: Mon | BM3: Mon | BN3: Mon | BO3: Mon | BP3: Tue | BQ3: Tue | BR3: Tue | BS3: Tue | BT3: Wed | BU3: Wed | BV3: Wed | BW3: Wed | BX3: Thu | BY3: Thu | BZ3: Thu | CA3: Thu | CB3: Fri | CC3: Fri | CD3: Fri | CE3: Fri | CF3: Sat | CG3: Sat | CH3: Sat | CI3: Mon | CJ3: Mon | CK3: Mon | CL3: Mon | CM3: Tue | CN3: Tue | CO3: Tue | CP3: Tue | CQ3: Wed | CR3: Wed | CS3: Wed | CT3: Wed | CU3: Thu | CV3: Thu | CW3: Thu | CX3: Thu | CY3: Fri | CZ3: Fri | DA3: Fri | DB3: Fri | DC3: Sat | DD3: Sat | DE3: Sat | DF3: Mon | DG3: Mon | DH3: Mon | DI3: Mon | DJ3: Tue | DK3: Tue | DL3: Tue | DM3: Tue | DN3: Wed | DO3: Wed | DP3: Wed | DQ3: Wed | DR3: Thu | DS3: Thu | DT3: Thu | DU3: Thu | DV3: Fri | DW3: Fri | DX3: Fri | DY3: Fri | DZ3: Sat | EA3: Sat | EB3: Sat | EC3: Mon | ED3: Mon | EE3: Mon | EF3: Mon | EG3: Tue | EH3: Tue | EI3: Tue | EJ3: Tue | EK3: Wed | EL3: Wed | EM3: Wed | EN3: Wed | EO3: Thu | EP3: Thu | EQ3: Thu | ER3: Thu | ES3: Fri | ET3: Fri | EU3: Fri | EV3: Fri | EW3: Mon | EX3: Mon | EY3: Mon | EZ3: Mon | FA3: Tue | FB3: Tue | FC3: Tue | FD3: Tue | FE3: Wed | FF3: Wed | FG3: Wed | FH3: Wed | FI3: Thu | FJ3: Thu | FK3: Thu | FL3: Thu | FM3: Mon | FN3: Mon | FO3: Mon | FP3: Mon | FQ3: Tue | FR3: Tue | FS3: Tue | FT3: Tue | FU3: Wed | FV3: Wed | FW3: Wed | FX3: Wed | FY3: Thu | FZ3: Thu | GA3: Thu | GB3: Thu | GC3: Fri | GD3: Fri | GE3: Fri | GF3: Fri | GG3: Sat | GH3: Sat | GI3: Sat
A4: 1 | B4: 325106410001 | C4: RATISH SHARMA | D4: P | I4: A | L4: A | P4: P | Q4: P | T4: P | AC4: P | AF4: P | AJ4: P | AK4: P | AN4: P | AR4: A | AW4: P | AZ4: P | BA4: P | BD4: P | BE4: P | BH4: P | BI4: A | BQ4: P | BT4: P | BU4: P | BX4: P | BY4: P | CB4: P | CF4: P | CN4: P | CQ4: P | CR4: P | CU4: P | CV4: P | CZ4: P | DC4: P | DK4: P | DN4: P | DO4: P | DR4: P | DS4: P | DV4: P | DW4: P | DZ4: A | EH4: A | EK4: P | EL4: P | EO4: P | EP4: P | ES4: P | ET4: P | FB4: P | FE4: P | FF4: P | FI4: P | FJ4: P | FR4: P | FY4: P | FZ4: P | GD4: P | GG4: P
A5: 2 | B5: 325106410002 | C5: ABDUL REHMAN | D5: A | I5: A | L5: A | P5: A | Q5: A | T5: P | AC5: P | AF5: P | AJ5: A | AK5: A | AN5: P | AR5: A | AW5: P | AZ5: A | BA5: A | BD5: P | BE5: P | BH5: P | BI5: A | BQ5: P | BT5: P | BU5: P | BX5: P | BY5: P | CB5: A | CF5: A | CN5: P | CQ5: P | CR5: P | CU5: P | CV5: P | CZ5: A | DC5: P | DK5: P | DN5: P | DO5: P | DR5: P | DS5: P | DV5: A | DW5: A | DZ5: P | EH5: P | EK5: P | EL5: P | EO5: A | EP5: A | ES5: P | ET5: P | FB5: P | FE5: P | FF5: P | FI5: P | FJ5: P | FR5: P | FY5: A | FZ5: A | GD5: A | GG5: P
A6: 3 | B6: 325106410003 | C6: RISHITHA AKUMARTHI | D6: A | I6: A | L6: A | P6: A | Q6: A | T6: A | AC6: A | AF6: A | AJ6: A | AK6: A | AN6: A | AR6: P | AW6: P | AZ6: P | BA6: P | BD6: P | BE6: P | BH6: P | BI6: P | BQ6: P | BT6: P | BU6: P | BX6: P | BY6: P | CB6: A | CF6: P | CN6: P | CQ6: P | CR6: A | CU6: P | CV6: P | CZ6: P | DC6: P | DK6: P | DN6: A | DO6: P | DR6: A | DS6: P | DV6: P | DW6: P | DZ6: A | EH6: P | EK6: P | EL6: P | EO6: P | EP6: P | ES6: P | ET6: P | FB6: P | FE6: P | FF6: P | FI6: P | FJ6: P | FR6: P | FY6: A | FZ6: A | GD6: P | GG6: A
A7: 4 | B7: 325106410004 | C7: SIREESHA BADANA | D7: A | I7: A | L7: A | P7: A | Q7: A | T7: A | AC7: A | AF7: A | AJ7: A | AK7: A | AN7: A | AR7: A | AW7: A | AZ7: A | BA7: A | BD7: A | BE7: A | BH7: A | BI7: A | BQ7: A | BT7: A | BU7: A | BX7: A | BY7: A | CB7: A | CF7: A | CN7: A | CQ7: A | CR7: A | CU7: A | CV7: A | CZ7: A | DC7: A | DK7: A | DN7: A | DO7: A | DR7: A | DS7: A | DV7: A | DW7: A | DZ7: P | EH7: A | EK7: A | EL7: A | EO7: A | EP7: A | ES7: A | ET7: A | FB7: A | FE7: A | FF7: A | FI7: A | FJ7: A | FR7: A | FY7: A | FZ7: A | GD7: A | GG7: A
A8: 5 | B8: 325106410005 | C8: LAKSHMANA KUMAR BATHULA | D8: A | I8: A | L8: A | P8: A | Q8: A | T8: A | AC8: P | AF8: P | AJ8: P | AK8: P | AN8: P | AR8: A | AW8: P | AZ8: P | BA8: P | BD8: P | BE8: P | BH8: P | BI8: P | BQ8: P | BT8: P | BU8: P | BX8: P | BY8: P | CB8: P | CF8: P | CN8: P | CQ8: P | CR8: P | CU8: P | CV8: P | CZ8: P | DC8: P | DK8: P | DN8: P | DO8: P | DR8: P | DS8: P | DV8: P | DW8: P | DZ8: P | EH8: P | EK8: P | EL8: P | EO8: P | EP8: P | ES8: P | ET8: P | FB8: A | FE8: P | FF8: P | FI8: P | FJ8: P | FR8: P | FY8: P | FZ8: P | GD8: P | GG8: P
A9: 6 | B9: 325106410006 | C9: PADMA KUMARI CHIKKALA | D9: A | I9: A | L9: A | P9: A | Q9: A | T9: A | AC9: A | AF9: P | AJ9: P | AK9: P | AN9: A | AR9: A | AW9: P | AZ9: P | BA9: P | BD9: P | BE9: P | BH9: P | BI9: P | BQ9: P | BT9: P | BU9: P | BX9: P | BY9: P | CB9: P | CF9: P | CN9: P | CQ9: P | CR9: P | CU9: P | CV9: P | CZ9: P | DC9: P | DK9: P | DN9: P | DO9: P | DR9: P | DS9: P | DV9: P | DW9: P | DZ9: A | EH9: P | EK9: A | EL9: P | EO9: P | EP9: P | ES9: P | ET9: P | FB9: P | FE9: P | FF9: P | FI9: P | FJ9: P | FR9: P | FY9: A | FZ9: A | GD9: P | GG9: P
A10: 7 | B10: 325106410007 | C10: RAKESH CHOPPA | D10: A | I10: A | L10: P | P10: P | Q10: P | T10: P | AC10: P | AF10: P | AJ10: P | AK10: P | AN10: P | AR10: P | AW10: P | AZ10: P | BA10: P | BD10: P | BE10: P | BH10: P | BI10: P | BQ10: P | BT10: P | BU10: P | BX10: A | BY10: A | CB10: P | CF10: P | CN10: P | CQ10: P | CR10: P | CU10: P | CV10: P | CZ10: P | DC10: A | DK10: P | DN10: P | DO10: P | DR10: P | DS10: P | DV10: P | DW10: P | DZ10: P | EH10: A | EK10: P | EL10: P | EO10: P | EP10: P | ES10: P | ET10: P | FB10: P | FE10: P | FF10: P | FI10: P | FJ10: P | FR10: P | FY10: P | FZ10: P | GD10: P | GG10: P
A11: 8 | B11: 325106410008 | C11: SUBHASH DHULIPUDI | D11: A | I11: A | L11: A | P11: P | Q11: P | T11: P | AC11: P | AF11: P | AJ11: P | AK11: P | AN11: P | AR11: P | AW11: P | AZ11: P | BA11: P | BD11: P | BE11: P | BH11: P | BI11: P | BQ11: P | BT11: P | BU11: P | BX11: P | BY11: P | CB11: P | CF11: P | CN11: P | CQ11: P | CR11: P | CU11: A | CV11: P | CZ11: P | DC11: P | DK11: P | DN11: P | DO11: P | DR11: P | DS11: P | DV11: P | DW11: P | DZ11: A | EH11: P | EK11: P | EL11: P | EO11: P | EP11: P | ES11: P | ET11: P | FB11: P | FE11: P | FF11: P | FI11: P | FJ11: P | FR11: P | FY11: P | FZ11: P | GD11: P | GG11: P
A12: 9 | B12: 325106410009 | C12: SRAVANI DUMMU | D12: A | I12: A | L12: P | P12: A | Q12: A | T12: A | AC12: A | AF12: P | AJ12: P | AK12: P | AN12: P | AR12: P | AW12: P | AZ12: P | BA12: P | BD12: P | BE12: P | BH12: P | BI12: P | BQ12: P | BT12: P | BU12: P | BX12: P | BY12: P | CB12: P | CF12: P | CN12: P | CQ12: P | CR12: P | CU12: P | CV12: P | CZ12: A | DC12: P | DK12: P | DN12: P | DO12: P | DR12: P | DS12: P | DV12: P | DW12: P | DZ12: P | EH12: P | EK12: P | EL12: P | EO12: P | EP12: P | ES12: P | ET12: P | FB12: P | FE12: P | FF12: P | FI12: P | FJ12: P | FR12: P | FY12: P | FZ12: P | GD12: A | GG12: A
A13: 10 | B13: 325106410010 | C13: EESHAAN URLAM | D13: A | I13: A | L13: A | P13: A | Q13: A | T13: A | AC13: P | AF13: P | AJ13: P | AK13: P | AN13: P | AR13: A | AW13: P | AZ13: P | BA13: P | BD13: P | BE13: P | BH13: P | BI13: P | BQ13: P | BT13: P | BU13: P | BX13: P | BY13: P | CB13: P | CF13: P | CN13: P | CQ13: P | CR13: P | CU13: A | CV13: A | CZ13: P | DC13: P | DK13: P | DN13: P | DO13: P | DR13: P | DS13: P | DV13: P | DW13: P | DZ13: A | EH13: P | EK13: P | EL13: P | EO13: P | EP13: P | ES13: P | ET13: P | FB13: P | FE13: P | FF13: P | FI13: P | FJ13: P | FR13: P | FY13: P | FZ13: A | GD13: A | GG13: P
A14: 11 | B14: 325106410011 | C14: KAILASH REDDY GADI | D14: A | I14: A | L14: P | P14: P | Q14: P | T14: A | AC14: P | AF14: P | AJ14: P | AK14: P | AN14: P | AR14: P | AW14: P | AZ14: P | BA14: P | BD14: P | BE14: P | BH14: P | BI14: P | BQ14: P | BT14: A | BU14: A | BX14: P | BY14: P | CB14: P | CF14: A | CN14: P | CQ14: P | CR14: P | CU14: A | CV14: A | CZ14: P | DC14: P | DK14: P | DN14: P | DO14: P | DR14: P | DS14: P | DV14: P | DW14: P | DZ14: P | EH14: P | EK14: P | EL14: P | EO14: P | EP14: P | ES14: P | ET14: P | FB14: P | FE14: P | FF14: P | FI14: P | FJ14: P | FR14: P | FY14: P | FZ14: P | GD14: P | GG14: P
A15: 12 | B15: 325106410012 | C15: DEEPIKA GANTA | D15: A | I15: A | L15: A | P15: A | Q15: A | T15: A | AC15: A | AF15: A | AJ15: A | AK15: A | AN15: A | AR15: A | AW15: P | AZ15: P | BA15: P | BD15: P | BE15: P | BH15: P | BI15: P | BQ15: P | BT15: P | BU15: P | BX15: P | BY15: P | CB15: P | CF15: P | CN15: P | CQ15: P | CR15: P | CU15: P | CV15: P | CZ15: P | DC15: P | DK15: P | DN15: P | DO15: P | DR15: P | DS15: P | DV15: P | DW15: P | DZ15: P | EH15: P | EK15: P | EL15: P | EO15: P | EP15: P | ES15: P | ET15: P | FB15: P | FE15: P | FF15: P | FI15: P | FJ15: P | FR15: P | FY15: P | FZ15: P | GD15: A | GG15: P
... A127: 124 | B127: 325106410124 | C127: YUVRAJ SINGH | D127: A | I127: A | L127: A | P127: A | Q127: A | T127: A | AC127: A | AF127: A | AJ127: A | AK127: A | AN127: A | AR127: A | AW127: P | AZ127: A | BA127: A | BD127: P | BE127: P | BH127: P | BI127: A | BQ127: P | BT127: P | BU127: P | BX127: P | BY127: P | CB127: P | CF127: A | CN127: P | CQ127: P | CR127: P | CU127: P | CV127: P | CZ127: A | DC127: P | DK127: P | DN127: P | DO127: P | DR127: P | DS127: P | DV127: A | DW127: A | DZ127: P | EH127: P | EK127: P | EL127: P | EO127: A | EP127: P | ES127: P | ET127: P | FB127: P | FE127: P | FF127: P | FI127: P | FJ127: P | FR127: P | FY127: P | FZ127: P | GD127: A | GG127: A

Sheet Monthly Summary
D1: JUNE — Subject-wise & Total Attendance | Y1: JULY — Subject-wise & Total Attendance | AT1: AUGUST — Subject-wise & Total Attendance | BO1: OVERALL (Jun+Jul+Aug) — Subject-wise & Total | CJ1: GRAND TOTAL (Theory 1x + Lab 2x)
D2: PSQT P | E2: PSQT A | F2: PSQT % | G2: OOPJ P | H2: OOPJ A | I2: OOPJ % | J2: OS P | K2: OS A | L2: OS % | M2: COA P | N2: COA A | O2: COA % | P2: DMS P | Q2: DMS A | R2: DMS % | S2: June Theory Total P | T2: June Theory Total A | U2: June Theory Total % | V2: June Lab P | W2: June Lab A | X2: June Lab % | Y2: PSQT P | Z2: PSQT A | AA2: PSQT % | AB2: OOPJ P | AC2: OOPJ A | AD2: OOPJ % | AE2: OS P | AF2: OS A | AG2: OS % | AH2: COA P | AI2: COA A | AJ2: COA % | AK2: DMS P | AL2: DMS A | AM2: DMS % | AN2: July Theory Total P | AO2: July Theory Total A | AP2: July Theory Total % | AQ2: July Lab P | AR2: July Lab A | AS2: July Lab % | AT2: PSQT P | AU2: PSQT A | AV2: PSQT % | AW2: OOPJ P | AX2: OOPJ A | AY2: OOPJ % | AZ2: OS P | BA2: OS A | BB2: OS % | BC2: COA P | BD2: COA A | BE2: COA % | BF2: DMS P | BG2: DMS A | BH2: DMS % | BI2: Aug Theory Total P | BJ2: Aug Theory Total A | BK2: Aug Theory Total % | BL2: Aug Lab P | BM2: Aug Lab A | BN2: Aug Lab % | BO2: PSQT Overall P | BP2: PSQT Overall A | BQ2: PSQT Overall % | BR2: OOPJ Overall P | BS2: OOPJ Overall A | BT2: OOPJ Overall % | BU2: OS Overall P | BV2: OS Overall A | BW2: OS Overall % | BX2: COA Overall P | BY2: COA Overall A | BZ2: COA Overall % | CA2: DMS Overall P | CB2: DMS Overall A | CC2: DMS Overall % | CD2: Overall Theory Total P | CE2: Overall Theory Total A | CF2: Overall Theory Total % | CG2: Overall Lab P | CH2: Overall Lab A | CI2: Overall Lab % | CJ2: Grand Total Present (Units) | CK2: Grand Total Absent (Units) | CL2: Grand Overall % (Theory=1x, Lab=2x) | CM2: Lab Batch
A3: 1 | B3: 325106410001 | C3: RATISH SHARMA | D3: 0 | E3: 0 | F3: =IF((D3+E3)=0,"", D3/(D3+E3)) | G3: =COUNTIF('Detailed Attendance'!I4:I4, "P") | H3: =COUNTIF('Detailed Attendance'!I4:I4, "A") | I3: =IF((G3+H3)=0,"", G3/(G3+H3)) | J3: 0 | K3: 0 | L3: =IF((J3+K3)=0,"", J3/(J3+K3)) | M3: =COUNTIF('Detailed Attendance'!D4:D4, "P") | N3: =COUNTIF('Detailed Attendance'!D4:D4, "A") | O3: =IF((M3+N3)=0,"", M3/(M3+N3)) | P3: 0 | Q3: 0 | R3: =IF((P3+Q3)=0,"", P3/(P3+Q3)) | S3: =D3+G3+J3+M3+P3 | T3: =E3+H3+K3+N3+Q3 | U3: =IF((S3+T3)=0,"", S3/(S3+T3)) | V3: =COUNTIF('Detailed Attendance'!E4:E4, "P") | W3: =COUNTIF('Detailed Attendance'!E4:E4, "A") | X3: =IF((V3+W3)=0,"", V3/(V3+W3)) | Y3: =COUNTIF('Detailed Attendance'!R4:R4, "P")+COUNTIF('Detailed Attendance'!X4:X4, "P")+COUNTIF('Detailed Attendance'!AL4:AL4, "P")+COUNTIF('Detailed Attendance'!BF4:BF4, "P")+COUNTIF('Detailed Attendance'!BL4:BL4, "P")+COUNTIF('Detailed Attendance'!BZ4:BZ4, "P")+COUNTIF('Detailed Attendance'!CI4:CI4, "P")+COUNTIF('Detailed Attendance'!CW4:CW4, "P") | Z3: =COUNTIF('Detailed Attendance'!R4:R4, "A")+COUNTIF('Detailed Attendance'!X4:X4, "A")+COUNTIF('Detailed Attendance'!AL4:AL4, "A")+COUNTIF('Detailed Attendance'!BF4:BF4, "A")+COUNTIF('Detailed Attendance'!BL4:BL4, "A")+COUNTIF('Detailed Attendance'!BZ4:BZ4, "A")+COUNTIF('Detailed Attendance'!CI4:CI4, "A")+COUNTIF('Detailed Attendance'!CW4:CW4, "A") | AA3: =IF((Y3+Z3)=0,"", Y3/(Y3+Z3)) | AB3: =COUNTIF('Detailed Attendance'!Q4:Q4, "P")+COUNTIF('Detailed Attendance'!AC4:AC4, "P")+COUNTIF('Detailed Attendance'!AK4:AK4, "P")+COUNTIF('Detailed Attendance'!AW4:AW4, "P")+COUNTIF('Detailed Attendance'!BE4:BE4, "P")+COUNTIF('Detailed Attendance'!BQ4:BQ4, "P")+COUNTIF('Detailed Attendance'!BY4:BY4, "P")+COUNTIF('Detailed Attendance'!CN4:CN4, "P")+COUNTIF('Detailed Attendance'!CV4:CV4, "P") | AC3: =COUNTIF('Detailed Attendance'!Q4:Q4, "A")+COUNTIF('Detailed Attendance'!AC4:AC4, "A")+COUNTIF('Detailed Attendance'!AK4:AK4, "A")+COUNTIF('Detailed Attendance'!AW4:AW4, "A")+COUNTIF('Detailed Attendance'!BE4:BE4, "A")+COUNTIF('Detailed Attendance'!BQ4:BQ4, "A")+COUNTIF('Detailed Attendance'!BY4:BY4, "A")+COUNTIF('Detailed Attendance'!CN4:CN4, "A")+COUNTIF('Detailed Attendance'!CV4:CV4, "A") | AD3: =IF((AB3+AC3)=0,"", AB3/(AB3+AC3)) | AE3: =COUNTIF('Detailed Attendance'!L4:L4, "P")+COUNTIF('Detailed Attendance'!P4:P4, "P")+COUNTIF('Detailed Attendance'!AF4:AF4, "P")+COUNTIF('Detailed Attendance'!AJ4:AJ4, "P")+COUNTIF('Detailed Attendance'!AZ4:AZ4, "P")+COUNTIF('Detailed Attendance'!BD4:BD4, "P")+COUNTIF('Detailed Attendance'!BT4:BT4, "P")+COUNTIF('Detailed Attendance'!BX4:BX4, "P")+COUNTIF('Detailed Attendance'!CQ4:CQ4, "P")+COUNTIF('Detailed Attendance'!CU4:CU4, "P") | AF3: =COUNTIF('Detailed Attendance'!L4:L4, "A")+COUNTIF('Detailed Attendance'!P4:P4, "A")+COUNTIF('Detailed Attendance'!AF4:AF4, "A")+COUNTIF('Detailed Attendance'!AJ4:AJ4, "A")+COUNTIF('Detailed Attendance'!AZ4:AZ4, "A")+COUNTIF('Detailed Attendance'!BD4:BD4, "A")+COUNTIF('Detailed Attendance'!BT4:BT4, "A")+COUNTIF('Detailed Attendance'!BX4:BX4, "A")+COUNTIF('Detailed Attendance'!CQ4:CQ4, "A")+COUNTIF('Detailed Attendance'!CU4:CU4, "A") | AG3: =IF((AE3+AF3)=0,"", AE3/(AE3+AF3)) | AH3: =COUNTIF('Detailed Attendance'!T4:T4, "P")+COUNTIF('Detailed Attendance'!AN4:AN4, "P")+COUNTIF('Detailed Attendance'!AR4:AR4, "P")+COUNTIF('Detailed Attendance'!BH4:BH4, "P")+COUNTIF('Detailed Attendance'!CB4:CB4, "P")+COUNTIF('Detailed Attendance'!CF4:CF4, "P")+COUNTIF('Detailed Attendance'!CY4:CY4, "P") | AI3: =COUNTIF('Detailed Attendance'!T4:T4, "A")+COUNTIF('Detailed Attendance'!AN4:AN4, "A")+COUNTIF('Detailed Attendance'!AR4:AR4, "A")+COUNTIF('Detailed Attendance'!BH4:BH4, "A")+COUNTIF('Detailed Attendance'!CB4:CB4, "A")+COUNTIF('Detailed Attendance'!CF4:CF4, "A")+COUNTIF('Detailed Attendance'!CY4:CY4, "A") | AJ3: =IF((AH3+AI3)=0,"", AH3/(AH3+AI3)) | AK3: =COUNTIF('Detailed Attendance'!M4:M4, "P")+COUNTIF('Detailed Attendance'!U4:U4, "P")+COUNTIF('Detailed Attendance'!AG4:AG4, "P")+COUNTIF('Detailed Attendance'!AO4:AO4, "P")+COUNTIF('Detailed Attendance'!BA4:BA4, "P")+COUNTIF('Detailed Attendance'!BI4:BI4, "P")+COUNTIF('Detailed Attendance'!BU4:BU4, "P")+COUNTIF('Detailed Attendance'!CC4:CC4, "P")+COUNTIF('Detailed Attendance'!CR4:CR4, "P")+COUNTIF('Detailed Attendance'!CZ4:CZ4, "P") | AL3: =COUNTIF('Detailed Attendance'!M4:M4, "A")+COUNTIF('Detailed Attendance'!U4:U4, "A")+COUNTIF('Detailed Attendance'!AG4:AG4, "A")+COUNTIF('Detailed Attendance'!AO4:AO4, "A")+COUNTIF('Detailed Attendance'!BA4:BA4, "A")+COUNTIF('Detailed Attendance'!BI4:BI4, "A")+COUNTIF('Detailed Attendance'!BU4:BU4, "A")+COUNTIF('Detailed Attendance'!CC4:CC4, "A")+COUNTIF('Detailed Attendance'!CR4:CR4, "A")+COUNTIF('Detailed Attendance'!CZ4:CZ4, "A") | AM3: =IF((AK3+AL3)=0,"", AK3/(AK3+AL3)) | AN3: =Y3+AB3+AE3+AH3+AK3 | AO3: =Z3+AC3+AF3+AI3+AL3 | AP3: =IF((AN3+AO3)=0,"", AN3/(AN3+AO3)) | AQ3: =COUNTIF('Detailed Attendance'!Y4:Y4, "P")+COUNTIF('Detailed Attendance'!AS4:AS4, "P")+COUNTIF('Detailed Attendance'!BM4:BM4, "P")+COUNTIF('Detailed Attendance'!CJ4:CJ4, "P")+COUNTIF('Detailed Attendance'!V4:V4, "P")+COUNTIF('Detailed Attendance'!AP4:AP4, "P")+COUNTIF('Detailed Attendance'!BJ4:BJ4, "P")+COUNTIF('Detailed Attendance'!CD4:CD4, "P")+COUNTIF('Detailed Attendance'!DA4:DA4, "P")+COUNTIF('Detailed Attendance'!CH4:CH4, "P") | AR3: =COUNTIF('Detailed Attendance'!Y4:Y4, "A")+COUNTIF('Detailed Attendance'!AS4:AS4, "A")+COUNTIF('Detailed Attendance'!BM4:BM4, "A")+COUNTIF('Detailed Attendance'!CJ4:CJ4, "A")+COUNTIF('Detailed Attendance'!V4:V4, "A")+COUNTIF('Detailed Attendance'!AP4:AP4, "A")+COUNTIF('Detailed Attendance'!BJ4:BJ4, "A")+COUNTIF('Detailed Attendance'!CD4:CD4, "A")+COUNTIF('Detailed Attendance'!DA4:DA4, "A")+COUNTIF('Detailed Attendance'!CH4:CH4, "A") | AS3: =IF((AQ3+AR3)=0,"", AQ3/(AQ3+AR3)) | AT3: =COUNTIF('Detailed Attendance'!DF4:DF4, "P")+COUNTIF('Detailed Attendance'!DT4:DT4, "P")+COUNTIF('Detailed Attendance'!EC4:EC4, "P")+COUNTIF('Detailed Attendance'!EQ4:EQ4, "P")+COUNTIF('Detailed Attendance'!EW4:EW4, "P")+COUNTIF('Detailed Attendance'!FK4:FK4, "P")+COUNTIF('Detailed Attendance'!FM4:FM4, "P")+COUNTIF('Detailed Attendance'!GA4:GA4, "P") | AU3: =COUNTIF('Detailed Attendance'!DF4:DF4, "A")+COUNTIF('Detailed Attendance'!DT4:DT4, "A")+COUNTIF('Detailed Attendance'!EC4:EC4, "A")+COUNTIF('Detailed Attendance'!EQ4:EQ4, "A")+COUNTIF('Detailed Attendance'!EW4:EW4, "A")+COUNTIF('Detailed Attendance'!FK4:FK4, "A")+COUNTIF('Detailed Attendance'!FM4:FM4, "A")+COUNTIF('Detailed Attendance'!GA4:GA4, "A") | AV3: =IF((AT3+AU3)=0,"", AT3/(AT3+AU3)) | AW3: =COUNTIF('Detailed Attendance'!DK4:DK4, "P")+COUNTIF('Detailed Attendance'!DS4:DS4, "P")+COUNTIF('Detailed Attendance'!EH4:EH4, "P")+COUNTIF('Detailed Attendance'!EP4:EP4, "P")+COUNTIF('Detailed Attendance'!FB4:FB4, "P")+COUNTIF('Detailed Attendance'!FJ4:FJ4, "P")+COUNTIF('Detailed Attendance'!FR4:FR4, "P")+COUNTIF('Detailed Attendance'!FZ4:FZ4, "P") | AX3: =COUNTIF('Detailed Attendance'!DK4:DK4, "A")+COUNTIF('Detailed Attendance'!DS4:DS4, "A")+COUNTIF('Detailed Attendance'!EH4:EH4, "A")+COUNTIF('Detailed Attendance'!EP4:EP4, "A")+COUNTIF('Detailed Attendance'!FB4:FB4, "A")+COUNTIF('Detailed Attendance'!FJ4:FJ4, "A")+COUNTIF('Detailed Attendance'!FR4:FR4, "A")+COUNTIF('Detailed Attendance'!FZ4:FZ4, "A") | AY3: =IF((AW3+AX3)=0,"", AW3/(AW3+AX3)) | AZ3: =COUNTIF('Detailed Attendance'!DN4:DN4, "P")+COUNTIF('Detailed Attendance'!DR4:DR4, "P")+COUNTIF('Detailed Attendance'!EK4:EK4, "P")+COUNTIF('Detailed Attendance'!EO4:EO4, "P")+COUNTIF('Detailed Attendance'!FE4:FE4, "P")+COUNTIF('Detailed Attendance'!FI4:FI4, "P")+COUNTIF('Detailed Attendance'!FU4:FU4, "P")+COUNTIF('Detailed Attendance'!FY4:FY4, "P") | BA3: =COUNTIF('Detailed Attendance'!DN4:DN4, "A")+COUNTIF('Detailed Attendance'!DR4:DR4, "A")+COUNTIF('Detailed Attendance'!EK4:EK4, "A")+COUNTIF('Detailed Attendance'!EO4:EO4, "A")+COUNTIF('Detailed Attendance'!FE4:FE4, "A")+COUNTIF('Detailed Attendance'!FI4:FI4, "A")+COUNTIF('Detailed Attendance'!FU4:FU4, "A")+COUNTIF('Detailed Attendance'!FY4:FY4, "A") | BB3: =IF((AZ3+BA3)=0,"", AZ3/(AZ3+BA3)) | BC3: =COUNTIF('Detailed Attendance'!DC4:DC4, "P")+COUNTIF('Detailed Attendance'!DV4:DV4, "P")+COUNTIF('Detailed Attendance'!DZ4:DZ4, "P")+COUNTIF('Detailed Attendance'!ES4:ES4, "P")+COUNTIF('Detailed Attendance'!GC4:GC4, "P")+COUNTIF('Detailed Attendance'!GG4:GG4, "P") | BD3: =COUNTIF('Detailed Attendance'!DC4:DC4, "A")+COUNTIF('Detailed Attendance'!DV4:DV4, "A")+COUNTIF('Detailed Attendance'!DZ4:DZ4, "A")+COUNTIF('Detailed Attendance'!ES4:ES4, "A")+COUNTIF('Detailed Attendance'!GC4:GC4, "A")+COUNTIF('Detailed Attendance'!GG4:GG4, "A") | BE3: =IF((BC3+BD3)=0,"", BC3/(BC3+BD3)) | BF3: =COUNTIF('Detailed Attendance'!DO4:DO4, "P")+COUNTIF('Detailed Attendance'!DW4:DW4, "P")+COUNTIF('Detailed Attendance'!EL4:EL4, "P")+COUNTIF('Detailed Attendance'!ET4:ET4, "P")+COUNTIF('Detailed Attendance'!FF4:FF4, "P")+COUNTIF('Detailed Attendance'!FV4:FV4, "P")+COUNTIF('Detailed Attendance'!GD4:GD4, "P") | BG3: =COUNTIF('Detailed Attendance'!DO4:DO4, "A")+COUNTIF('Detailed Attendance'!DW4:DW4, "A")+COUNTIF('Detailed Attendance'!EL4:EL4, "A")+COUNTIF('Detailed Attendance'!ET4:ET4, "A")+COUNTIF('Detailed Attendance'!FF4:FF4, "A")+COUNTIF('Detailed Attendance'!FV4:FV4, "A")+COUNTIF('Detailed Attendance'!GD4:GD4, "A") | BH3: =IF((BF3+BG3)=0,"", BF3/(BF3+BG3)) | BI3: =AT3+AW3+AZ3+BC3+BF3 | BJ3: =AU3+AX3+BA3+BD3+BG3 | BK3: =IF((BI3+BJ3)=0,"", BI3/(BI3+BJ3)) | BL3: =COUNTIF('Detailed Attendance'!DG4:DG4, "P")+COUNTIF('Detailed Attendance'!ED4:ED4, "P")+COUNTIF('Detailed Attendance'!EX4:EX4, "P")+COUNTIF('Detailed Attendance'!FN4:FN4, "P")+COUNTIF('Detailed Attendance'!DX4:DX4, "P")+COUNTIF('Detailed Attendance'!EU4:EU4, "P")+COUNTIF('Detailed Attendance'!GE4:GE4, "P")+COUNTIF('Detailed Attendance'!DE4:DE4, "P")+COUNTIF('Detailed Attendance'!EB4:EB4, "P")+COUNTIF('Detailed Attendance'!GI4:GI4, "P") | BM3: =COUNTIF('Detailed Attendance'!DG4:DG4, "A")+COUNTIF('Detailed Attendance'!ED4:ED4, "A")+COUNTIF('Detailed Attendance'!EX4:EX4, "A")+COUNTIF('Detailed Attendance'!FN4:FN4, "A")+COUNTIF('Detailed Attendance'!DX4:DX4, "A")+COUNTIF('Detailed Attendance'!EU4:EU4, "A")+COUNTIF('Detailed Attendance'!GE4:GE4, "A")+COUNTIF('Detailed Attendance'!DE4:DE4, "A")+COUNTIF('Detailed Attendance'!EB4:EB4, "A")+COUNTIF('Detailed Attendance'!GI4:GI4, "A") | BN3: =IF((BL3+BM3)=0,"", BL3/(BL3+BM3)) | BO3: =D3+Y3+AT3 | BP3: =E3+Z3+AU3 | BQ3: =IF((BO3+BP3)=0,"", BO3/(BO3+BP3)) | BR3: =G3+AB3+AW3 | BS3: =H3+AC3+AX3 | BT3: =IF((BR3+BS3)=0,"", BR3/(BR3+BS3)) | BU3: =J3+AE3+AZ3 | BV3: =K3+AF3+BA3 | BW3: =IF((BU3+BV3)=0,"", BU3/(BU3+BV3)) | BX3: =M3+AH3+BC3 | BY3: =N3+AI3+BD3 | BZ3: =IF((BX3+BY3)=0,"", BX3/(BX3+BY3)) | CA3: =P3+AK3+BF3 | CB3: =Q3+AL3+BG3 | CC3: =IF((CA3+CB3)=0,"", CA3/(CA3+CB3)) | CD3: =S3+AN3+BI3 | CE3: =T3+AO3+BJ3 | CF3: =IF((CD3+CE3)=0,"", CD3/(CD3+CE3)) | CG3: =V3+AQ3+BL3 | CH3: =W3+AR3+BM3 | CI3: =IF((CG3+CH3)=0,"", CG3/(CG3+CH3)) | CJ3: =CD3+(CG3*2) | CK3: =CE3+(CH3*2) | CL3: =IF((CJ3+CK3)=0,"", CJ3/(CJ3+CK3)) | CM3: Batch 1
A4: 2 | B4: 325106410002 | C4: ABDUL REHMAN | D4: 0 | E4: 0 | F4: =IF((D4+E4)=0,"", D4/(D4+E4)) | G4: =COUNTIF('Detailed Attendance'!I5:I5, "P") | H4: =COUNTIF('Detailed Attendance'!I5:I5, "A") | I4: =IF((G4+H4)=0,"", G4/(G4+H4)) | J4: 0 | K4: 0 | L4: =IF((J4+K4)=0,"", J4/(J4+K4)) | M4: =COUNTIF('Detailed Attendance'!D5:D5, "P") | N4: =COUNTIF('Detailed Attendance'!D5:D5, "A") | O4: =IF((M4+N4)=0,"", M4/(M4+N4)) | P4: 0 | Q4: 0 | R4: =IF((P4+Q4)=0,"", P4/(P4+Q4)) | S4: =D4+G4+J4+M4+P4 | T4: =E4+H4+K4+N4+Q4 | U4: =IF((S4+T4)=0,"", S4/(S4+T4)) | V4: =COUNTIF('Detailed Attendance'!E5:E5, "P") | W4: =COUNTIF('Detailed Attendance'!E5:E5, "A") | X4: =IF((V4+W4)=0,"", V4/(V4+W4)) | Y4: =COUNTIF('Detailed Attendance'!R5:R5, "P")+COUNTIF('Detailed Attendance'!X5:X5, "P")+COUNTIF('Detailed Attendance'!AL5:AL5, "P")+COUNTIF('Detailed Attendance'!BF5:BF5, "P")+COUNTIF('Detailed Attendance'!BL5:BL5, "P")+COUNTIF('Detailed Attendance'!BZ5:BZ5, "P")+COUNTIF('Detailed Attendance'!CI5:CI5, "P")+COUNTIF('Detailed Attendance'!CW5:CW5, "P") | Z4: =COUNTIF('Detailed Attendance'!R5:R5, "A")+COUNTIF('Detailed Attendance'!X5:X5, "A")+COUNTIF('Detailed Attendance'!AL5:AL5, "A")+COUNTIF('Detailed Attendance'!BF5:BF5, "A")+COUNTIF('Detailed Attendance'!BL5:BL5, "A")+COUNTIF('Detailed Attendance'!BZ5:BZ5, "A")+COUNTIF('Detailed Attendance'!CI5:CI5, "A")+COUNTIF('Detailed Attendance'!CW5:CW5, "A") | AA4: =IF((Y4+Z4)=0,"", Y4/(Y4+Z4)) | AB4: =COUNTIF('Detailed Attendance'!Q5:Q5, "P")+COUNTIF('Detailed Attendance'!AC5:AC5, "P")+COUNTIF('Detailed Attendance'!AK5:AK5, "P")+COUNTIF('Detailed Attendance'!AW5:AW5, "P")+COUNTIF('Detailed Attendance'!BE5:BE5, "P")+COUNTIF('Detailed Attendance'!BQ5:BQ5, "P")+COUNTIF('Detailed Attendance'!BY5:BY5, "P")+COUNTIF('Detailed Attendance'!CN5:CN5, "P")+COUNTIF('Detailed Attendance'!CV5:CV5, "P") | AC4: =COUNTIF('Detailed Attendance'!Q5:Q5, "A")+COUNTIF('Detailed Attendance'!AC5:AC5, "A")+COUNTIF('Detailed Attendance'!AK5:AK5, "A")+COUNTIF('Detailed Attendance'!AW5:AW5, "A")+COUNTIF('Detailed Attendance'!BE5:BE5, "A")+COUNTIF('Detailed Attendance'!BQ5:BQ5, "A")+COUNTIF('Detailed Attendance'!BY5:BY5, "A")+COUNTIF('Detailed Attendance'!CN5:CN5, "A")+COUNTIF('Detailed Attendance'!CV5:CV5, "A") | AD4: =IF((AB4+AC4)=0,"", AB4/(AB4+AC4)) | AE4: =COUNTIF('Detailed Attendance'!L5:L5, "P")+COUNTIF('Detailed Attendance'!P5:P5, "P")+COUNTIF('Detailed Attendance'!AF5:AF5, "P")+COUNTIF('Detailed Attendance'!AJ5:AJ5, "P")+COUNTIF('Detailed Attendance'!AZ5:AZ5, "P")+COUNTIF('Detailed Attendance'!BD5:BD5, "P")+COUNTIF('Detailed Attendance'!BT5:BT5, "P")+COUNTIF('Detailed Attendance'!BX5:BX5, "P")+COUNTIF('Detailed Attendance'!CQ5:CQ5, "P")+COUNTIF('Detailed Attendance'!CU5:CU5, "P") | AF4: =COUNTIF('Detailed Attendance'!L5:L5, "A")+COUNTIF('Detailed Attendance'!P5:P5, "A")+COUNTIF('Detailed Attendance'!AF5:AF5, "A")+COUNTIF('Detailed Attendance'!AJ5:AJ5, "A")+COUNTIF('Detailed Attendance'!AZ5:AZ5, "A")+COUNTIF('Detailed Attendance'!BD5:BD5, "A")+COUNTIF('Detailed Attendance'!BT5:BT5, "A")+COUNTIF('Detailed Attendance'!BX5:BX5, "A")+COUNTIF('Detailed Attendance'!CQ5:CQ5, "A")+COUNTIF('Detailed Attendance'!CU5:CU5, "A") | AG4: =IF((AE4+AF4)=0,"", AE4/(AE4+AF4)) | AH4: =COUNTIF('Detailed Attendance'!T5:T5, "P")+COUNTIF('Detailed Attendance'!AN5:AN5, "P")+COUNTIF('Detailed Attendance'!AR5:AR5, "P")+COUNTIF('Detailed Attendance'!BH5:BH5, "P")+COUNTIF('Detailed Attendance'!CB5:CB5, "P")+COUNTIF('Detailed Attendance'!CF5:CF5, "P")+COUNTIF('Detailed Attendance'!CY5:CY5, "P") | AI4: =COUNTIF('Detailed Attendance'!T5:T5, "A")+COUNTIF('Detailed Attendance'!AN5:AN5, "A")+COUNTIF('Detailed Attendance'!AR5:AR5, "A")+COUNTIF('Detailed Attendance'!BH5:BH5, "A")+COUNTIF('Detailed Attendance'!CB5:CB5, "A")+COUNTIF('Detailed Attendance'!CF5:CF5, "A")+COUNTIF('Detailed Attendance'!CY5:CY5, "A") | AJ4: =IF((AH4+AI4)=0,"", AH4/(AH4+AI4)) | AK4: =COUNTIF('Detailed Attendance'!M5:M5, "P")+COUNTIF('Detailed Attendance'!U5:U5, "P")+COUNTIF('Detailed Attendance'!AG5:AG5, "P")+COUNTIF('Detailed Attendance'!AO5:AO5, "P")+COUNTIF('Detailed Attendance'!BA5:BA5, "P")+COUNTIF('Detailed Attendance'!BI5:BI5, "P")+COUNTIF('Detailed Attendance'!BU5:BU5, "P")+COUNTIF('Detailed Attendance'!CC5:CC5, "P")+COUNTIF('Detailed Attendance'!CR5:CR5, "P")+COUNTIF('Detailed Attendance'!CZ5:CZ5, "P") | AL4: =COUNTIF('Detailed Attendance'!M5:M5, "A")+COUNTIF('Detailed Attendance'!U5:U5, "A")+COUNTIF('Detailed Attendance'!AG5:AG5, "A")+COUNTIF('Detailed Attendance'!AO5:AO5, "A")+COUNTIF('Detailed Attendance'!BA5:BA5, "A")+COUNTIF('Detailed Attendance'!BI5:BI5, "A")+COUNTIF('Detailed Attendance'!BU5:BU5, "A")+COUNTIF('Detailed Attendance'!CC5:CC5, "A")+COUNTIF('Detailed Attendance'!CR5:CR5, "A")+COUNTIF('Detailed Attendance'!CZ5:CZ5, "A") | AM4: =IF((AK4+AL4)=0,"", AK4/(AK4+AL4)) | AN4: =Y4+AB4+AE4+AH4+AK4 | AO4: =Z4+AC4+AF4+AI4+AL4 | AP4: =IF((AN4+AO4)=0,"", AN4/(AN4+AO4)) | AQ4: =COUNTIF('Detailed Attendance'!Y5:Y5, "P")+COUNTIF('Detailed Attendance'!AS5:AS5, "P")+COUNTIF('Detailed Attendance'!BM5:BM5, "P")+COUNTIF('Detailed Attendance'!CJ5:CJ5, "P")+COUNTIF('Detailed Attendance'!V5:V5, "P")+COUNTIF('Detailed Attendance'!AP5:AP5, "P")+COUNTIF('Detailed Attendance'!BJ5:BJ5, "P")+COUNTIF('Detailed Attendance'!CD5:CD5, "P")+COUNTIF('Detailed Attendance'!DA5:DA5, "P")+COUNTIF('Detailed Attendance'!CH5:CH5, "P") | AR4: =COUNTIF('Detailed Attendance'!Y5:Y5, "A")+COUNTIF('Detailed Attendance'!AS5:AS5, "A")+COUNTIF('Detailed Attendance'!BM5:BM5, "A")+COUNTIF('Detailed Attendance'!CJ5:CJ5, "A")+COUNTIF('Detailed Attendance'!V5:V5, "A")+COUNTIF('Detailed Attendance'!AP5:AP5, "A")+COUNTIF('Detailed Attendance'!BJ5:BJ5, "A")+COUNTIF('Detailed Attendance'!CD5:CD5, "A")+COUNTIF('Detailed Attendance'!DA5:DA5, "A")+COUNTIF('Detailed Attendance'!CH5:CH5, "A") | AS4: =IF((AQ4+AR4)=0,"", AQ4/(AQ4+AR4)) | AT4: =COUNTIF('Detailed Attendance'!DF5:DF5, "P")+COUNTIF('Detailed Attendance'!DT5:DT5, "P")+COUNTIF('Detailed Attendance'!EC5:EC5, "P")+COUNTIF('Detailed Attendance'!EQ5:EQ5, "P")+COUNTIF('Detailed Attendance'!EW5:EW5, "P")+COUNTIF('Detailed Attendance'!FK5:FK5, "P")+COUNTIF('Detailed Attendance'!FM5:FM5, "P")+COUNTIF('Detailed Attendance'!GA5:GA5, "P") | AU4: =COUNTIF('Detailed Attendance'!DF5:DF5, "A")+COUNTIF('Detailed Attendance'!DT5:DT5, "A")+COUNTIF('Detailed Attendance'!EC5:EC5, "A")+COUNTIF('Detailed Attendance'!EQ5:EQ5, "A")+COUNTIF('Detailed Attendance'!EW5:EW5, "A")+COUNTIF('Detailed Attendance'!FK5:FK5, "A")+COUNTIF('Detailed Attendance'!FM5:FM5, "A")+COUNTIF('Detailed Attendance'!GA5:GA5, "A") | AV4: =IF((AT4+AU4)=0,"", AT4/(AT4+AU4)) | AW4: =COUNTIF('Detailed Attendance'!DK5:DK5, "P")+COUNTIF('Detailed Attendance'!DS5:DS5, "P")+COUNTIF('Detailed Attendance'!EH5:EH5, "P")+COUNTIF('Detailed Attendance'!EP5:EP5, "P")+COUNTIF('Detailed Attendance'!FB5:FB5, "P")+COUNTIF('Detailed Attendance'!FJ5:FJ5, "P")+COUNTIF('Detailed Attendance'!FR5:FR5, "P")+COUNTIF('Detailed Attendance'!FZ5:FZ5, "P") | AX4: =COUNTIF('Detailed Attendance'!DK5:DK5, "A")+COUNTIF('Detailed Attendance'!DS5:DS5, "A")+COUNTIF('Detailed Attendance'!EH5:EH5, "A")+COUNTIF('Detailed Attendance'!EP5:EP5, "A")+COUNTIF('Detailed Attendance'!FB5:FB5, "A")+COUNTIF('Detailed Attendance'!FJ5:FJ5, "A")+COUNTIF('Detailed Attendance'!FR5:FR5, "A")+COUNTIF('Detailed Attendance'!FZ5:FZ5, "A") | AY4: =IF((AW4+AX4)=0,"", AW4/(AW4+AX4)) | AZ4: =COUNTIF('Detailed Attendance'!DN5:DN5, "P")+COUNTIF('Detailed Attendance'!DR5:DR5, "P")+COUNTIF('Detailed Attendance'!EK5:EK5, "P")+COUNTIF('Detailed Attendance'!EO5:EO5, "P")+COUNTIF('Detailed Attendance'!FE5:FE5, "P")+COUNTIF('Detailed Attendance'!FI5:FI5, "P")+COUNTIF('Detailed Attendance'!FU5:FU5, "P")+COUNTIF('Detailed Attendance'!FY5:FY5, "P") | BA4: =COUNTIF('Detailed Attendance'!DN5:DN5, "A")+COUNTIF('Detailed Attendance'!DR5:DR5, "A")+COUNTIF('Detailed Attendance'!EK5:EK5, "A")+COUNTIF('Detailed Attendance'!EO5:EO5, "A")+COUNTIF('Detailed Attendance'!FE5:FE5, "A")+COUNTIF('Detailed Attendance'!FI5:FI5, "A")+COUNTIF('Detailed Attendance'!FU5:FU5, "A")+COUNTIF('Detailed Attendance'!FY5:FY5, "A") | BB4: =IF((AZ4+BA4)=0,"", AZ4/(AZ4+BA4)) | BC4: =COUNTIF('Detailed Attendance'!DC5:DC5, "P")+COUNTIF('Detailed Attendance'!DV5:DV5, "P")+COUNTIF('Detailed Attendance'!DZ5:DZ5, "P")+COUNTIF('Detailed Attendance'!ES5:ES5, "P")+COUNTIF('Detailed Attendance'!GC5:GC5, "P")+COUNTIF('Detailed Attendance'!GG5:GG5, "P") | BD4: =COUNTIF('Detailed Attendance'!DC5:DC5, "A")+COUNTIF('Detailed Attendance'!DV5:DV5, "A")+COUNTIF('Detailed Attendance'!DZ5:DZ5, "A")+COUNTIF('Detailed Attendance'!ES5:ES5, "A")+COUNTIF('Detailed Attendance'!GC5:GC5, "A")+COUNTIF('Detailed Attendance'!GG5:GG5, "A") | BE4: =IF((BC4+BD4)=0,"", BC4/(BC4+BD4)) | BF4: =COUNTIF('Detailed Attendance'!DO5:DO5, "P")+COUNTIF('Detailed Attendance'!DW5:DW5, "P")+COUNTIF('Detailed Attendance'!EL5:EL5, "P")+COUNTIF('Detailed Attendance'!ET5:ET5, "P")+COUNTIF('Detailed Attendance'!FF5:FF5, "P")+COUNTIF('Detailed Attendance'!FV5:FV5, "P")+COUNTIF('Detailed Attendance'!GD5:GD5, "P") | BG4: =COUNTIF('Detailed Attendance'!DO5:DO5, "A")+COUNTIF('Detailed Attendance'!DW5:DW5, "A")+COUNTIF('Detailed Attendance'!EL5:EL5, "A")+COUNTIF('Detailed Attendance'!ET5:ET5, "A")+COUNTIF('Detailed Attendance'!FF5:FF5, "A")+COUNTIF('Detailed Attendance'!FV5:FV5, "A")+COUNTIF('Detailed Attendance'!GD5:GD5, "A") | BH4: =IF((BF4+BG4)=0,"", BF4/(BF4+BG4)) | BI4: =AT4+AW4+AZ4+BC4+BF4 | BJ4: =AU4+AX4+BA4+BD4+BG4 | BK4: =IF((BI4+BJ4)=0,"", BI4/(BI4+BJ4)) | BL4: =COUNTIF('Detailed Attendance'!DG5:DG5, "P")+COUNTIF('Detailed Attendance'!ED5:ED5, "P")+COUNTIF('Detailed Attendance'!EX5:EX5, "P")+COUNTIF('Detailed Attendance'!FN5:FN5, "P")+COUNTIF('Detailed Attendance'!DX5:DX5, "P")+COUNTIF('Detailed Attendance'!EU5:EU5, "P")+COUNTIF('Detailed Attendance'!GE5:GE5, "P")+COUNTIF('Detailed Attendance'!DE5:DE5, "P")+COUNTIF('Detailed Attendance'!EB5:EB5, "P")+COUNTIF('Detailed Attendance'!GI5:GI5, "P") | BM4: =COUNTIF('Detailed Attendance'!DG5:DG5, "A")+COUNTIF('Detailed Attendance'!ED5:ED5, "A")+COUNTIF('Detailed Attendance'!EX5:EX5, "A")+COUNTIF('Detailed Attendance'!FN5:FN5, "A")+COUNTIF('Detailed Attendance'!DX5:DX5, "A")+COUNTIF('Detailed Attendance'!EU5:EU5, "A")+COUNTIF('Detailed Attendance'!GE5:GE5, "A")+COUNTIF('Detailed Attendance'!DE5:DE5, "A")+COUNTIF('Detailed Attendance'!EB5:EB5, "A")+COUNTIF('Detailed Attendance'!GI5:GI5, "A") | BN4: =IF((BL4+BM4)=0,"", BL4/(BL4+BM4)) | BO4: =D4+Y4+AT4 | BP4: =E4+Z4+AU4 | BQ4: =IF((BO4+BP4)=0,"", BO4/(BO4+BP4)) | BR4: =G4+AB4+AW4 | BS4: =H4+AC4+AX4 | BT4: =IF((BR4+BS4)=0,"", BR4/(BR4+BS4)) | BU4: =J4+AE4+AZ4 | BV4: =K4+AF4+BA4 | BW4: =IF((BU4+BV4)=0,"", BU4/(BU4+BV4)) | BX4: =M4+AH4+BC4 | BY4: =N4+AI4+BD4 | BZ4: =IF((BX4+BY4)=0,"", BX4/(BX4+BY4)) | CA4: =P4+AK4+BF4 | CB4: =Q4+AL4+BG4 | CC4: =IF((CA4+CB4)=0,"", CA4/(CA4+CB4)) | CD4: =S4+AN4+BI4 | CE4: =T4+AO4+BJ4 | CF4: =IF((CD4+CE4)=0,"", CD4/(CD4+CE4)) | CG4: =V4+AQ4+BL4 | CH4: =W4+AR4+BM4 | CI4: =IF((CG4+CH4)=0,"", CG4/(CG4+CH4)) | CJ4: =CD4+(CG4*2) | CK4: =CE4+(CH4*2) | CL4: =IF((CJ4+CK4)=0,"", CJ4/(CJ4+CK4)) | CM4: Batch 1
A5: 3 | B5: 325106410003 | C5: RISHITHA AKUMARTHI | D5: 0 | E5: 0 | F5: =IF((D5+E5)=0,"", D5/(D5+E5)) | G5: =COUNTIF('Detailed Attendance'!I6:I6, "P") | H5: =COUNTIF('Detailed Attendance'!I6:I6, "A") | I5: =IF((G5+H5)=0,"", G5/(G5+H5)) | J5: 0 | K5: 0 | L5: =IF((J5+K5)=0,"", J5/(J5+K5)) | M5: =COUNTIF('Detailed Attendance'!D6:D6, "P") | N5: =COUNTIF('Detailed Attendance'!D6:D6, "A") | O5: =IF((M5+N5)=0,"", M5/(M5+N5)) | P5: 0 | Q5: 0 | R5: =IF((P5+Q5)=0,"", P5/(P5+Q5)) | S5: =D5+G5+J5+M5+P5 | T5: =E5+H5+K5+N5+Q5 | U5: =IF((S5+T5)=0,"", S5/(S5+T5)) | V5: =COUNTIF('Detailed Attendance'!E6:E6, "P") | W5: =COUNTIF('Detailed Attendance'!E6:E6, "A") | X5: =IF((V5+W5)=0,"", V5/(V5+W5)) | Y5: =COUNTIF('Detailed Attendance'!R6:R6, "P")+COUNTIF('Detailed Attendance'!X6:X6, "P")+COUNTIF('Detailed Attendance'!AL6:AL6, "P")+COUNTIF('Detailed Attendance'!BF6:BF6, "P")+COUNTIF('Detailed Attendance'!BL6:BL6, "P")+COUNTIF('Detailed Attendance'!BZ6:BZ6, "P")+COUNTIF('Detailed Attendance'!CI6:CI6, "P")+COUNTIF('Detailed Attendance'!CW6:CW6, "P") | Z5: =COUNTIF('Detailed Attendance'!R6:R6, "A")+COUNTIF('Detailed Attendance'!X6:X6, "A")+COUNTIF('Detailed Attendance'!AL6:AL6, "A")+COUNTIF('Detailed Attendance'!BF6:BF6, "A")+COUNTIF('Detailed Attendance'!BL6:BL6, "A")+COUNTIF('Detailed Attendance'!BZ6:BZ6, "A")+COUNTIF('Detailed Attendance'!CI6:CI6, "A")+COUNTIF('Detailed Attendance'!CW6:CW6, "A") | AA5: =IF((Y5+Z5)=0,"", Y5/(Y5+Z5)) | AB5: =COUNTIF('Detailed Attendance'!Q6:Q6, "P")+COUNTIF('Detailed Attendance'!AC6:AC6, "P")+COUNTIF('Detailed Attendance'!AK6:AK6, "P")+COUNTIF('Detailed Attendance'!AW6:AW6, "P")+COUNTIF('Detailed Attendance'!BE6:BE6, "P")+COUNTIF('Detailed Attendance'!BQ6:BQ6, "P")+COUNTIF('Detailed Attendance'!BY6:BY6, "P")+COUNTIF('Detailed Attendance'!CN6:CN6, "P")+COUNTIF('Detailed Attendance'!CV6:CV6, "P") | AC5: =COUNTIF('Detailed Attendance'!Q6:Q6, "A")+COUNTIF('Detailed Attendance'!AC6:AC6, "A")+COUNTIF('Detailed Attendance'!AK6:AK6, "A")+COUNTIF('Detailed Attendance'!AW6:AW6, "A")+COUNTIF('Detailed Attendance'!BE6:BE6, "A")+COUNTIF('Detailed Attendance'!BQ6:BQ6, "A")+COUNTIF('Detailed Attendance'!BY6:BY6, "A")+COUNTIF('Detailed Attendance'!CN6:CN6, "A")+COUNTIF('Detailed Attendance'!CV6:CV6, "A") | AD5: =IF((AB5+AC5)=0,"", AB5/(AB5+AC5)) | AE5: =COUNTIF('Detailed Attendance'!L6:L6, "P")+COUNTIF('Detailed Attendance'!P6:P6, "P")+COUNTIF('Detailed Attendance'!AF6:AF6, "P")+COUNTIF('Detailed Attendance'!AJ6:AJ6, "P")+COUNTIF('Detailed Attendance'!AZ6:AZ6, "P")+COUNTIF('Detailed Attendance'!BD6:BD6, "P")+COUNTIF('Detailed Attendance'!BT6:BT6, "P")+COUNTIF('Detailed Attendance'!BX6:BX6, "P")+COUNTIF('Detailed Attendance'!CQ6:CQ6, "P")+COUNTIF('Detailed Attendance'!CU6:CU6, "P") | AF5: =COUNTIF('Detailed Attendance'!L6:L6, "A")+COUNTIF('Detailed Attendance'!P6:P6, "A")+COUNTIF('Detailed Attendance'!AF6:AF6, "A")+COUNTIF('Detailed Attendance'!AJ6:AJ6, "A")+COUNTIF('Detailed Attendance'!AZ6:AZ6, "A")+COUNTIF('Detailed Attendance'!BD6:BD6, "A")+COUNTIF('Detailed Attendance'!BT6:BT6, "A")+COUNTIF('Detailed Attendance'!BX6:BX6, "A")+COUNTIF('Detailed Attendance'!CQ6:CQ6, "A")+COUNTIF('Detailed Attendance'!CU6:CU6, "A") | AG5: =IF((AE5+AF5)=0,"", AE5/(AE5+AF5)) | AH5: =COUNTIF('Detailed Attendance'!T6:T6, "P")+COUNTIF('Detailed Attendance'!AN6:AN6, "P")+COUNTIF('Detailed Attendance'!AR6:AR6, "P")+COUNTIF('Detailed Attendance'!BH6:BH6, "P")+COUNTIF('Detailed Attendance'!CB6:CB6, "P")+COUNTIF('Detailed Attendance'!CF6:CF6, "P")+COUNTIF('Detailed Attendance'!CY6:CY6, "P") | AI5: =COUNTIF('Detailed Attendance'!T6:T6, "A")+COUNTIF('Detailed Attendance'!AN6:AN6, "A")+COUNTIF('Detailed Attendance'!AR6:AR6, "A")+COUNTIF('Detailed Attendance'!BH6:BH6, "A")+COUNTIF('Detailed Attendance'!CB6:CB6, "A")+COUNTIF('Detailed Attendance'!CF6:CF6, "A")+COUNTIF('Detailed Attendance'!CY6:CY6, "A") | AJ5: =IF((AH5+AI5)=0,"", AH5/(AH5+AI5)) | AK5: =COUNTIF('Detailed Attendance'!M6:M6, "P")+COUNTIF('Detailed Attendance'!U6:U6, "P")+COUNTIF('Detailed Attendance'!AG6:AG6, "P")+COUNTIF('Detailed Attendance'!AO6:AO6, "P")+COUNTIF('Detailed Attendance'!BA6:BA6, "P")+COUNTIF('Detailed Attendance'!BI6:BI6, "P")+COUNTIF('Detailed Attendance'!BU6:BU6, "P")+COUNTIF('Detailed Attendance'!CC6:CC6, "P")+COUNTIF('Detailed Attendance'!CR6:CR6, "P")+COUNTIF('Detailed Attendance'!CZ6:CZ6, "P") | AL5: =COUNTIF('Detailed Attendance'!M6:M6, "A")+COUNTIF('Detailed Attendance'!U6:U6, "A")+COUNTIF('Detailed Attendance'!AG6:AG6, "A")+COUNTIF('Detailed Attendance'!AO6:AO6, "A")+COUNTIF('Detailed Attendance'!BA6:BA6, "A")+COUNTIF('Detailed Attendance'!BI6:BI6, "A")+COUNTIF('Detailed Attendance'!BU6:BU6, "A")+COUNTIF('Detailed Attendance'!CC6:CC6, "A")+COUNTIF('Detailed Attendance'!CR6:CR6, "A")+COUNTIF('Detailed Attendance'!CZ6:CZ6, "A") | AM5: =IF((AK5+AL5)=0,"", AK5/(AK5+AL5)) | AN5: =Y5+AB5+AE5+AH5+AK5 | AO5: =Z5+AC5+AF5+AI5+AL5 | AP5: =IF((AN5+AO5)=0,"", AN5/(AN5+AO5)) | AQ5: =COUNTIF('Detailed Attendance'!Y6:Y6, "P")+COUNTIF('Detailed Attendance'!AS6:AS6, "P")+COUNTIF('Detailed Attendance'!BM6:BM6, "P")+COUNTIF('Detailed Attendance'!CJ6:CJ6, "P")+COUNTIF('Detailed Attendance'!V6:V6, "P")+COUNTIF('Detailed Attendance'!AP6:AP6, "P")+COUNTIF('Detailed Attendance'!BJ6:BJ6, "P")+COUNTIF('Detailed Attendance'!CD6:CD6, "P")+COUNTIF('Detailed Attendance'!DA6:DA6, "P")+COUNTIF('Detailed Attendance'!CH6:CH6, "P") | AR5: =COUNTIF('Detailed Attendance'!Y6:Y6, "A")+COUNTIF('Detailed Attendance'!AS6:AS6, "A")+COUNTIF('Detailed Attendance'!BM6:BM6, "A")+COUNTIF('Detailed Attendance'!CJ6:CJ6, "A")+COUNTIF('Detailed Attendance'!V6:V6, "A")+COUNTIF('Detailed Attendance'!AP6:AP6, "A")+COUNTIF('Detailed Attendance'!BJ6:BJ6, "A")+COUNTIF('Detailed Attendance'!CD6:CD6, "A")+COUNTIF('Detailed Attendance'!DA6:DA6, "A")+COUNTIF('Detailed Attendance'!CH6:CH6, "A") | AS5: =IF((AQ5+AR5)=0,"", AQ5/(AQ5+AR5)) | AT5: =COUNTIF('Detailed Attendance'!DF6:DF6, "P")+COUNTIF('Detailed Attendance'!DT6:DT6, "P")+COUNTIF('Detailed Attendance'!EC6:EC6, "P")+COUNTIF('Detailed Attendance'!EQ6:EQ6, "P")+COUNTIF('Detailed Attendance'!EW6:EW6, "P")+COUNTIF('Detailed Attendance'!FK6:FK6, "P")+COUNTIF('Detailed Attendance'!FM6:FM6, "P")+COUNTIF('Detailed Attendance'!GA6:GA6, "P") | AU5: =COUNTIF('Detailed Attendance'!DF6:DF6, "A")+COUNTIF('Detailed Attendance'!DT6:DT6, "A")+COUNTIF('Detailed Attendance'!EC6:EC6, "A")+COUNTIF('Detailed Attendance'!EQ6:EQ6, "A")+COUNTIF('Detailed Attendance'!EW6:EW6, "A")+COUNTIF('Detailed Attendance'!FK6:FK6, "A")+COUNTIF('Detailed Attendance'!FM6:FM6, "A")+COUNTIF('Detailed Attendance'!GA6:GA6, "A") | AV5: =IF((AT5+AU5)=0,"", AT5/(AT5+AU5)) | AW5: =COUNTIF('Detailed Attendance'!DK6:DK6, "P")+COUNTIF('Detailed Attendance'!DS6:DS6, "P")+COUNTIF('Detailed Attendance'!EH6:EH6, "P")+COUNTIF('Detailed Attendance'!EP6:EP6, "P")+COUNTIF('Detailed Attendance'!FB6:FB6, "P")+COUNTIF('Detailed Attendance'!FJ6:FJ6, "P")+COUNTIF('Detailed Attendance'!FR6:FR6, "P")+COUNTIF('Detailed Attendance'!FZ6:FZ6, "P") | AX5: =COUNTIF('Detailed Attendance'!DK6:DK6, "A")+COUNTIF('Detailed Attendance'!DS6:DS6, "A")+COUNTIF('Detailed Attendance'!EH6:EH6, "A")+COUNTIF('Detailed Attendance'!EP6:EP6, "A")+COUNTIF('Detailed Attendance'!FB6:FB6, "A")+COUNTIF('Detailed Attendance'!FJ6:FJ6, "A")+COUNTIF('Detailed Attendance'!FR6:FR6, "A")+COUNTIF('Detailed Attendance'!FZ6:FZ6, "A") | AY5: =IF((AW5+AX5)=0,"", AW5/(AW5+AX5)) | AZ5: =COUNTIF('Detailed Attendance'!DN6:DN6, "P")+COUNTIF('Detailed Attendance'!DR6:DR6, "P")+COUNTIF('Detailed Attendance'!EK6:EK6, "P")+COUNTIF('Detailed Attendance'!EO6:EO6, "P")+COUNTIF('Detailed Attendance'!FE6:FE6, "P")+COUNTIF('Detailed Attendance'!FI6:FI6, "P")+COUNTIF('Detailed Attendance'!FU6:FU6, "P")+COUNTIF('Detailed Attendance'!FY6:FY6, "P") | BA5: =COUNTIF('Detailed Attendance'!DN6:DN6, "A")+COUNTIF('Detailed Attendance'!DR6:DR6, "A")+COUNTIF('Detailed Attendance'!EK6:EK6, "A")+COUNTIF('Detailed Attendance'!EO6:EO6, "A")+COUNTIF('Detailed Attendance'!FE6:FE6, "A")+COUNTIF('Detailed Attendance'!FI6:FI6, "A")+COUNTIF('Detailed Attendance'!FU6:FU6, "A")+COUNTIF('Detailed Attendance'!FY6:FY6, "A") | BB5: =IF((AZ5+BA5)=0,"", AZ5/(AZ5+BA5)) | BC5: =COUNTIF('Detailed Attendance'!DC6:DC6, "P")+COUNTIF('Detailed Attendance'!DV6:DV6, "P")+COUNTIF('Detailed Attendance'!DZ6:DZ6, "P")+COUNTIF('Detailed Attendance'!ES6:ES6, "P")+COUNTIF('Detailed Attendance'!GC6:GC6, "P")+COUNTIF('Detailed Attendance'!GG6:GG6, "P") | BD5: =COUNTIF('Detailed Attendance'!DC6:DC6, "A")+COUNTIF('Detailed Attendance'!DV6:DV6, "A")+COUNTIF('Detailed Attendance'!DZ6:DZ6, "A")+COUNTIF('Detailed Attendance'!ES6:ES6, "A")+COUNTIF('Detailed Attendance'!GC6:GC6, "A")+COUNTIF('Detailed Attendance'!GG6:GG6, "A") | BE5: =IF((BC5+BD5)=0,"", BC5/(BC5+BD5)) | BF5: =COUNTIF('Detailed Attendance'!DO6:DO6, "P")+COUNTIF('Detailed Attendance'!DW6:DW6, "P")+COUNTIF('Detailed Attendance'!EL6:EL6, "P")+COUNTIF('Detailed Attendance'!ET6:ET6, "P")+COUNTIF('Detailed Attendance'!FF6:FF6, "P")+COUNTIF('Detailed Attendance'!FV6:FV6, "P")+COUNTIF('Detailed Attendance'!GD6:GD6, "P") | BG5: =COUNTIF('Detailed Attendance'!DO6:DO6, "A")+COUNTIF('Detailed Attendance'!DW6:DW6, "A")+COUNTIF('Detailed Attendance'!EL6:EL6, "A")+COUNTIF('Detailed Attendance'!ET6:ET6, "A")+COUNTIF('Detailed Attendance'!FF6:FF6, "A")+COUNTIF('Detailed Attendance'!FV6:FV6, "A")+COUNTIF('Detailed Attendance'!GD6:GD6, "A") | BH5: =IF((BF5+BG5)=0,"", BF5/(BF5+BG5)) | BI5: =AT5+AW5+AZ5+BC5+BF5 | BJ5: =AU5+AX5+BA5+BD5+BG5 | BK5: =IF((BI5+BJ5)=0,"", BI5/(BI5+BJ5)) | BL5: =COUNTIF('Detailed Attendance'!DG6:DG6, "P")+COUNTIF('Detailed Attendance'!ED6:ED6, "P")+COUNTIF('Detailed Attendance'!EX6:EX6, "P")+COUNTIF('Detailed Attendance'!FN6:FN6, "P")+COUNTIF('Detailed Attendance'!DX6:DX6, "P")+COUNTIF('Detailed Attendance'!EU6:EU6, "P")+COUNTIF('Detailed Attendance'!GE6:GE6, "P")+COUNTIF('Detailed Attendance'!DE6:DE6, "P")+COUNTIF('Detailed Attendance'!EB6:EB6, "P")+COUNTIF('Detailed Attendance'!GI6:GI6, "P") | BM5: =COUNTIF('Detailed Attendance'!DG6:DG6, "A")+COUNTIF('Detailed Attendance'!ED6:ED6, "A")+COUNTIF('Detailed Attendance'!EX6:EX6, "A")+COUNTIF('Detailed Attendance'!FN6:FN6, "A")+COUNTIF('Detailed Attendance'!DX6:DX6, "A")+COUNTIF('Detailed Attendance'!EU6:EU6, "A")+COUNTIF('Detailed Attendance'!GE6:GE6, "A")+COUNTIF('Detailed Attendance'!DE6:DE6, "A")+COUNTIF('Detailed Attendance'!EB6:EB6, "A")+COUNTIF('Detailed Attendance'!GI6:GI6, "A") | BN5: =IF((BL5+BM5)=0,"", BL5/(BL5+BM5)) | BO5: =D5+Y5+AT5 | BP5: =E5+Z5+AU5 | BQ5: =IF((BO5+BP5)=0,"", BO5/(BO5+BP5)) | BR5: =G5+AB5+AW5 | BS5: =H5+AC5+AX5 | BT5: =IF((BR5+BS5)=0,"", BR5/(BR5+BS5)) | BU5: =J5+AE5+AZ5 | BV5: =K5+AF5+BA5 | BW5: =IF((BU5+BV5)=0,"", BU5/(BU5+BV5)) | BX5: =M5+AH5+BC5 | BY5: =N5+AI5+BD5 | BZ5: =IF((BX5+BY5)=0,"", BX5/(BX5+BY5)) | CA5: =P5+AK5+BF5 | CB5: =Q5+AL5+BG5 | CC5: =IF((CA5+CB5)=0,"", CA5/(CA5+CB5)) | CD5: =S5+AN5+BI5 | CE5: =T5+AO5+BJ5 | CF5: =IF((CD5+CE5)=0,"", CD5/(CD5+CE5)) | CG5: =V5+AQ5+BL5 | CH5: =W5+AR5+BM5 | CI5: =IF((CG5+CH5)=0,"", CG5/(CG5+CH5)) | CJ5: =CD5+(CG5*2) | CK5: =CE5+(CH5*2) | CL5: =IF((CJ5+CK5)=0,"", CJ5/(CJ5+CK5)) | CM5: Batch 1
